<?xml version="1.0"?>

<robot name="physics">

    <link name="ground"/>

    <link name="upper_motor">
        <visual>
            <geometry>
                <cylinder length="0.05" radius="0.04"/>
            </geometry>
            <origin rpy="1.5708 0 0"/>
        </visual>
    </link>

    <joint name="ground_upper_motor" type="revolute">
        <parent link="ground"/>
        <child link="upper_motor"/>
        <origin xyz="0 0 1"/>
        <axis xyz="1 0 0"/>
        <limit effort="0" lower="0" upper="0.3926" velocity="0"/>
    </joint>

    <link name="upper_leg">
        <visual>
            <geometry>
                <box size="0.4 0.05 0.05"/>
            </geometry>
            <origin xyz="0 0 -0.2" rpy="0 1.5708 0"/>
        </visual>
    </link>

    <joint name="upper_motor_leg_joint" type="fixed">
        <parent link="upper_motor"/>
        <child link="upper_leg"/>
    </joint>

    <link name="middle_motor">
        <visual>
            <geometry>
                <cylinder length="0.05" radius="0.04"/>
            </geometry>
            <origin xyz="0 0 0" rpy="1.5708 0 0"/>
        </visual>
    </link>

    <joint name="upper_leg_middle_motor_joint" type="revolute">
        <parent link="upper_leg"/>
        <child link="middle_motor"/>
        <origin xyz="0 0 -0.4"/>
        <axis xyz="0 -1 0"/>
        <limit effort="0" lower="-0.3926" upper="0.3926" velocity="0"/>
    </joint>


    <link name="middle_leg">
        <visual>
            <geometry>
                <box size="0.3 0.05 0.05"/>
            </geometry>
            <origin xyz="0 0 -0.125" rpy="0 1.5708 0"/>
        </visual>
    </link>

    <joint name="middle_motor_leg_joint" type="fixed">
        <parent link="middle_motor"/>
        <child link="middle_leg"/>
    </joint>

    <link name="lower_motor">
        <visual>
            <geometry>
                <cylinder length="0.05" radius="0.04"/>
            </geometry>
            <origin xyz="0 0 0" rpy="1.5708 0 0"/>
        </visual>
    </link>

    <joint name="middle_leg_lower_motor_joint" type="revolute">
        <parent link="middle_leg"/>
        <child link="lower_motor"/>
        <origin xyz="0 0 -0.3"/>
        <axis xyz="0 -1 0"/>
        <limit effort="0" lower="-0.5235" upper="0.5235" velocity="0"/>
    </joint>


    <link name="lower_leg">
        <visual>
            <geometry>
                <box size="0.25 0.04 0.04"/>
            </geometry>
            <origin xyz= "0 0 -0.125" rpy="0 1.5708 0"/>
        </visual>
    </link>

    <joint name="lower_motor_leg_joint" type="fixed">
        <parent link="lower_motor"/>
        <child link="lower_leg"/>
    </joint>



    <!-- <deformable name="feet">

        <inertial>
            <mass value="1" />
            <inertia ixx="0.0" ixy="0" ixz="0" iyy="0" iyz="0" izz="0" />
        </inertial>
        <visual filename="mysphere.vtk"/>
        <visual>
            <geometry>
                <sphere radius="0.06"/>
            </geometry>
            <origin xyz="0 0 -0.25"/>
        </visual>

        <collision>
            <geometry>
                <sphere radius="0.06"/>
            </geometry>
            <origin xyz="0 0 -0.25"/>
            <max_contacts>10</max_contacts>
        </collision>
        <collision_margin value="0.006"/>
        <repulsion_stiffness value="800.0"/>
        <friction value= "0.5"/>
        <neohookean mu= "60" lambda= "200" damping= "0.01" />
    </deformable> -->

    <link name="feet">
        <visual>
            <geometry>
                <box size="0.3 0.1 0.05"/>
            </geometry>  
            <origin xyz="0.1 0 -0.275" />  
        </visual>
        <!-- <collision>
            <geometry>
                <box size="0.3 0.1 0.025"/>   
            </geometry>
            <origin xyz="0.1 0 -0.3" />  
        </collision> -->
    </link>

    <joint name="lower_leg_feet_joint" type="fixed">
        <parent link="lower_leg"/>
        <child link="feet"/>
    </joint>


</robot>