<?xml version="1.0"?>

<robot name="physics">

    <link name="ground"/>

    <link name="leg">
        <visual>
            <geometry>
                <box size="0.03 0.02 0.5"/>
            </geometry>
            <origin xyz="0 0 -0.25"/>
        </visual>
        
    </link>

    <joint name="ground_leg_joint" type="continuous">
        <parent link="ground"/>
        <child link="leg"/>
        <origin xyz="0 0 0.8"/>
        <axis xyz="0 1 0"/>
    </joint>

    <link name="spot_foot">
      <visual>
        <origin rpy="-0.2 0 1.57079632679" xyz="-0.275 0.137 -0.11"/> 
        <geometry>
          <mesh filename="Spot_foot.stl" scale="1 1 1"/>
        </geometry>
        <material name="orange"/>
      </visual>
      <collision>
        <origin rpy="-0.2 0 1.57079632679" xyz="-0.275 0.137 -0.11"/> <!--rpy="0 0 1.57079632679"-->
        <geometry>
          <mesh filename="Spot_foot.stl" scale="1 1 1"/>
        </geometry>
        <contact_coefficients mu="10.1"/>
      </collision>
      <inertial>
        <mass value="0.005"/>
        <origin rpy="-0.2 0 1.57079632679" xyz="-0.275 0.137 -0.11"/>
        <!-- Inertial Axes -->
        <inertia ixx="3.52083333333e-06" ixy="0" ixz="0" iyx="0" iyy="2.80208333333e-06" iyz="0" izx="0" izy="0" izz="2.80208333333e-06"/>
      </inertial>
  </link>
  
    <joint name="leg_foot_joint" type="fixed">
        <parent link="leg"/>
        <child link="spot_foot"/>
        <origin xyz="0 0 -0.25"/>
    </joint>



</robot>