<?xml version="1.0"?>

<robot name="physics">

    <link name="ground"/>
      

    <link name="leg">
      <inertial>
        <mass value="0"/>
        <inertia ixx="0.0" ixy="0.0" ixz="0.0" iyy="0.0" iyz="0.0" izz="0.0"/>
      </inertial>
        <visual>
            <geometry>
                <box size="0.03 0.02 0.5"/>
            </geometry>
            <origin xyz="0 0 -0.25"/>
        </visual>
        
    </link>

    <joint name="ground_leg_joint" type="continuous">
        <parent link="ground"/>
        <child link="leg"/>
        <origin xyz="0 0 0.7"/>
        <axis xyz="0 1 0"/>
    </joint>

    <link name="spot_foot">

      <contact>
        <lateral_friction value="1.0"/>
        <rolling_friction value="0.0"/>
        <contact_cfm value="0.0"/>
        <contact_erp value="1.0"/>
      </contact>

      <visual>
        <origin xyz="0 0 -0.25"/> 
        <geometry>
          <mesh filename="spot_foot_centered.stl" scale="1.5 1.5 1.5"/>
        </geometry>
        <material name="orange"/>
      </visual>
      <collision>
         <origin xyz="0 0 -0.25"/>
        <geometry>
          <mesh filename="spot_foot_centered.stl" scale="1.5 1.5 1.5"/>
        </geometry>
        <contact_coefficients mu="10.1"/>
      </collision>
      <inertial>
        <mass value="0.005"/>
        <origin xyz="0 0 -0.25"/>
        <!-- Inertial Axes -->
        <inertia ixx="3.52083333333e-06" ixy="0" ixz="0" iyx="0" iyy="2.80208333333e-06" iyz="0" izx="0" izy="0" izz="2.80208333333e-06"/>
      </inertial>
  </link>
  
    <joint name="leg_foot_joint" type="fixed">
        <parent link="leg"/>
        <child link="spot_foot"/>
        <origin xyz="0 0 -0.25"/>
    </joint>



</robot>